Exception on /query [POST]
Traceback (most recent call last):
  File "/Users/lenox27/.pyenv/versions/3.11.6/lib/python3.11/site-packages/flask/app.py", line 1463, in wsgi_app
    response = self.full_dispatch_request()
               ^^^^^^^^^^^^^^^^^^^^^^^^^^^^
  File "/Users/lenox27/.pyenv/versions/3.11.6/lib/python3.11/site-packages/flask/app.py", line 872, in full_dispatch_request
    rv = self.handle_user_exception(e)
         ^^^^^^^^^^^^^^^^^^^^^^^^^^^^^
  File "/Users/lenox27/.pyenv/versions/3.11.6/lib/python3.11/site-packages/flask_cors/extension.py", line 176, in wrapped_function
    return cors_after_request(app.make_response(f(*args, **kwargs)))
                                                ^^^^^^^^^^^^^^^^^^
  File "/Users/lenox27/.pyenv/versions/3.11.6/lib/python3.11/site-packages/flask/app.py", line 870, in full_dispatch_request
    rv = self.dispatch_request()
         ^^^^^^^^^^^^^^^^^^^^^^^
  File "/Users/lenox27/.pyenv/versions/3.11.6/lib/python3.11/site-packages/flask/app.py", line 855, in dispatch_request
    return self.ensure_sync(self.view_functions[rule.endpoint])(**view_args)  # type: ignore[no-any-return]
           ^^^^^^^^^^^^^^^^^^^^^^^^^^^^^^^^^^^^^^^^^^^^^^^^^^^^^^^^^^^^^^^^^
  File "/Users/lenox27/LENOX/main.py", line 58, in handle_query
    response = lenox.convchain(query, session_id)
               ^^^^^^^^^^^^^^^^^^^^^^^^^^^^^^^^^^
  File "/Users/lenox27/LENOX/utils.py", line 68, in convchain
    result = self.chain_with_history.invoke({"input": query}, config={"configurable": {"session_id": self.session_id}})
             ^^^^^^^^^^^^^^^^^^^^^^^^^^^^^^^^^^^^^^^^^^^^^^^^^^^^^^^^^^^^^^^^^^^^^^^^^^^^^^^^^^^^^^^^^^^^^^^^^^^^^^^^^^
  File "/Users/lenox27/.pyenv/versions/3.11.6/lib/python3.11/site-packages/langchain_core/runnables/base.py", line 4219, in invoke
    return self.bound.invoke(
           ^^^^^^^^^^^^^^^^^^
  File "/Users/lenox27/.pyenv/versions/3.11.6/lib/python3.11/site-packages/langchain_core/runnables/base.py", line 4219, in invoke
    return self.bound.invoke(
           ^^^^^^^^^^^^^^^^^^
  File "/Users/lenox27/.pyenv/versions/3.11.6/lib/python3.11/site-packages/langchain_core/runnables/base.py", line 2218, in invoke
    input = step.invoke(
            ^^^^^^^^^^^^
  File "/Users/lenox27/.pyenv/versions/3.11.6/lib/python3.11/site-packages/langchain_core/runnables/base.py", line 4219, in invoke
    return self.bound.invoke(
           ^^^^^^^^^^^^^^^^^^
  File "/Users/lenox27/.pyenv/versions/3.11.6/lib/python3.11/site-packages/langchain_core/runnables/passthrough.py", line 453, in invoke
    return self._call_with_config(self._invoke, input, config, **kwargs)
           ^^^^^^^^^^^^^^^^^^^^^^^^^^^^^^^^^^^^^^^^^^^^^^^^^^^^^^^^^^^^^
  File "/Users/lenox27/.pyenv/versions/3.11.6/lib/python3.11/site-packages/langchain_core/runnables/base.py", line 1405, in _call_with_config
    context.run(
  File "/Users/lenox27/.pyenv/versions/3.11.6/lib/python3.11/site-packages/langchain_core/runnables/config.py", line 326, in call_func_with_variable_args
    return func(input, **kwargs)  # type: ignore[call-arg]
           ^^^^^^^^^^^^^^^^^^^^^
  File "/Users/lenox27/.pyenv/versions/3.11.6/lib/python3.11/site-packages/langchain_core/runnables/passthrough.py", line 440, in _invoke
    **self.mapper.invoke(
      ^^^^^^^^^^^^^^^^^^^
  File "/Users/lenox27/.pyenv/versions/3.11.6/lib/python3.11/site-packages/langchain_core/runnables/base.py", line 2855, in invoke
    output = {key: future.result() for key, future in zip(steps, futures)}
             ^^^^^^^^^^^^^^^^^^^^^^^^^^^^^^^^^^^^^^^^^^^^^^^^^^^^^^^^^^^^^
  File "/Users/lenox27/.pyenv/versions/3.11.6/lib/python3.11/site-packages/langchain_core/runnables/base.py", line 2855, in <dictcomp>
    output = {key: future.result() for key, future in zip(steps, futures)}
                   ^^^^^^^^^^^^^^^
  File "/Users/lenox27/.pyenv/versions/3.11.6/lib/python3.11/concurrent/futures/_base.py", line 449, in result
    return self.__get_result()
           ^^^^^^^^^^^^^^^^^^^
  File "/Users/lenox27/.pyenv/versions/3.11.6/lib/python3.11/concurrent/futures/_base.py", line 401, in __get_result
    raise self._exception
  File "/Users/lenox27/.pyenv/versions/3.11.6/lib/python3.11/concurrent/futures/thread.py", line 58, in run
    result = self.fn(*self.args, **self.kwargs)
             ^^^^^^^^^^^^^^^^^^^^^^^^^^^^^^^^^^
  File "/Users/lenox27/.pyenv/versions/3.11.6/lib/python3.11/site-packages/langchain_core/runnables/base.py", line 4219, in invoke
    return self.bound.invoke(
           ^^^^^^^^^^^^^^^^^^
  File "/Users/lenox27/.pyenv/versions/3.11.6/lib/python3.11/site-packages/langchain_core/runnables/base.py", line 3669, in invoke
    return self._call_with_config(
           ^^^^^^^^^^^^^^^^^^^^^^^
  File "/Users/lenox27/.pyenv/versions/3.11.6/lib/python3.11/site-packages/langchain_core/runnables/base.py", line 1405, in _call_with_config
    context.run(
  File "/Users/lenox27/.pyenv/versions/3.11.6/lib/python3.11/site-packages/langchain_core/runnables/config.py", line 326, in call_func_with_variable_args
    return func(input, **kwargs)  # type: ignore[call-arg]
           ^^^^^^^^^^^^^^^^^^^^^
  File "/Users/lenox27/.pyenv/versions/3.11.6/lib/python3.11/site-packages/langchain_core/runnables/base.py", line 3543, in _invoke
    output = call_func_with_variable_args(
             ^^^^^^^^^^^^^^^^^^^^^^^^^^^^^
  File "/Users/lenox27/.pyenv/versions/3.11.6/lib/python3.11/site-packages/langchain_core/runnables/config.py", line 326, in call_func_with_variable_args
    return func(input, **kwargs)  # type: ignore[call-arg]
           ^^^^^^^^^^^^^^^^^^^^^
  File "/Users/lenox27/.pyenv/versions/3.11.6/lib/python3.11/site-packages/langchain_core/runnables/history.py", line 409, in _enter_history
    return hist.messages.copy()
           ^^^^^^^^^^^^^^^^^^
AttributeError: 'function' object has no attribute 'copy'
Interner Serverfehler: 500 Internal Server Error: The server encountered an internal error and was unable to complete your request. Either the server is overloaded or there is an error in the application.
Flask application started
Flask application started
Flask application started
Flask application started
Flask application started
Flask application started
Flask application started
Flask application started
Flask application started
Flask application started
Flask application started
Flask application started
Flask application started
Flask application started
Flask application started
404 Nicht gefunden: 404 Not Found: The requested URL was not found on the server. If you entered the URL manually please check your spelling and try again.
Flask application started
404 Nicht gefunden: 404 Not Found: The requested URL was not found on the server. If you entered the URL manually please check your spelling and try again.
Flask application started
404 Nicht gefunden: 404 Not Found: The requested URL was not found on the server. If you entered the URL manually please check your spelling and try again.
Exception on /query [POST]
Traceback (most recent call last):
  File "/Users/lenox27/.pyenv/versions/3.11.6/lib/python3.11/site-packages/flask/app.py", line 1463, in wsgi_app
    response = self.full_dispatch_request()
               ^^^^^^^^^^^^^^^^^^^^^^^^^^^^
  File "/Users/lenox27/.pyenv/versions/3.11.6/lib/python3.11/site-packages/flask/app.py", line 872, in full_dispatch_request
    rv = self.handle_user_exception(e)
         ^^^^^^^^^^^^^^^^^^^^^^^^^^^^^
  File "/Users/lenox27/.pyenv/versions/3.11.6/lib/python3.11/site-packages/flask_cors/extension.py", line 176, in wrapped_function
    return cors_after_request(app.make_response(f(*args, **kwargs)))
                                                ^^^^^^^^^^^^^^^^^^
  File "/Users/lenox27/.pyenv/versions/3.11.6/lib/python3.11/site-packages/flask/app.py", line 870, in full_dispatch_request
    rv = self.dispatch_request()
         ^^^^^^^^^^^^^^^^^^^^^^^
  File "/Users/lenox27/.pyenv/versions/3.11.6/lib/python3.11/site-packages/flask/app.py", line 855, in dispatch_request
    return self.ensure_sync(self.view_functions[rule.endpoint])(**view_args)  # type: ignore[no-any-return]
           ^^^^^^^^^^^^^^^^^^^^^^^^^^^^^^^^^^^^^^^^^^^^^^^^^^^^^^^^^^^^^^^^^
  File "/Users/lenox27/LENOX/main.py", line 58, in handle_query
    response = lenox.convchain(query, session_id)
               ^^^^^^^^^^^^^^^^^^^^^^^^^^^^^^^^^^
  File "/Users/lenox27/LENOX/utils.py", line 61, in convchain
    return handler(query, chat_history, session_id)
        ^^^^^^^^^^^^^^^^^^^^^^^^^^^^^^^^^^^^^^^^
  File "/Users/lenox27/LENOX/utils.py", line 115, in handle_general_query
    prompt_text = self.create_prompt(context_messages, query)
                  ^^^^^^^^^^^^^^^^^^^^^^^^^^^^^^^^^^^^^^^^^^^
  File "/Users/lenox27/LENOX/utils.py", line 137, in create_prompt
    prompt_text = self.prompt_engine.generate_dynamic_prompt(user_query, context_messages)
                  ^^^^^^^^^^^^^^^^^^
AttributeError: 'Lenox' object has no attribute 'prompt_engine'
Interner Serverfehler: 500 Internal Server Error: The server encountered an internal error and was unable to complete your request. Either the server is overloaded or there is an error in the application.
Flask application started
404 Nicht gefunden: 404 Not Found: The requested URL was not found on the server. If you entered the URL manually please check your spelling and try again.
Flask application started
404 Nicht gefunden: 404 Not Found: The requested URL was not found on the server. If you entered the URL manually please check your spelling and try again.
Flask application started
404 Nicht gefunden: 404 Not Found: The requested URL was not found on the server. If you entered the URL manually please check your spelling and try again.
Flask application started
Flask application started
Flask application started
